Workbook
Name Base_Fee_Lkup: Sheet1!$F$1:$H$19
Name Bundle_Lkup: '[6]24) Lookup Information'!$E$20:$I$137
Name CF_Review_Period: '[6]24) Lookup Information'!$B$4
Name CF_Tax_Amort_Period: '[6]24) Lookup Information'!$B$5
Name clComplete: #REF!
Name clCustom1: #REF!
Name clCustom2: #REF!
Name clCustom3: #REF!
Name clCustom4: #REF!
Name clDelayed: #REF!
Name clInProgress: #REF!
Name clNotStarted: #REF!
Name ColData: 25
Name ColumnTitle1: #REF!
Name ColumnTitle2: #REF!
Name ColumnTitleRegion1..K4.1: #REF!
Name Conv_1: '[6]18) SBS R2 Cash Flow'!$G$17
Name Conv_2: '[6]18) SBS R2 Cash Flow'!$G$18
Name Conv_3: '[6]18) SBS R2 Cash Flow'!$G$19
Name Conv_4: '[6]18) SBS R2 Cash Flow'!$G$20
Name Conv_5: '[6]18) SBS R2 Cash Flow'!$G$21
Name Conv_6: '[6]18) SBS R2 Cash Flow'!$G$22
Name Conv_7: '[6]18) SBS R2 Cash Flow'!$G$23
Name CPA_Ret_Adj: '[6]24) Lookup Information'!$B$1
Name Delivery: Sheet1!$A$13:$A$14
Name DIYTax: [7]Sheet2!$B$1:$B$3
Name EssOptions: "A3000000000111000000001100000_01009#NoAccess"
Name EssSamplingValue: 100
Name Frequency: Sheet1!$A$2:$A$7
Name garn_wrap_up: '[8]garnishments & wrap up2'!$A$1:$J$181
Name MA_Field_NSE: '[6]24) Lookup Information'!$B$11
Name MA_Float_Cost: '[6]24) Lookup Information'!$B$9
Name MA_Float_Rev: '[6]24) Lookup Information'!$B$8
Name MA_Imp_Expense: '[6]24) Lookup Information'!$B$10
Name MA_Mgmt_NSE: '[6]24) Lookup Information'!$B$13
Name MA_Price_Increase: '[6]24) Lookup Information'!$B$7
Name MA_Tele_NSE: '[6]24) Lookup Information'!$B$12
Name MA_W2_Exp: '[6]24) Lookup Information'!$B$14
Name MADelivery: '[6]17) Pricing'!$GX$7
Name MASplitWrap: '[6]17) Pricing'!$GY$7
Name MATaxJ: '[6]17) Pricing'!$GZ$7
Name Names: #REF!
Name NSE_1: '[6]18) SBS R2 Cash Flow'!$F$17
Name NSE_2: '[6]18) SBS R2 Cash Flow'!$F$18
Name NSE_3: '[6]18) SBS R2 Cash Flow'!$F$19
Name NSE_4: '[6]18) SBS R2 Cash Flow'!$F$20
Name NSE_5: '[6]18) SBS R2 Cash Flow'!$F$21
Name NSE_6: '[6]18) SBS R2 Cash Flow'!$F$22
Name NSE_7: '[6]18) SBS R2 Cash Flow'!$F$23
Name Pay_Size_Label_Lkup: '[6]24) Lookup Information'!$A$144:$B$156
Name Price_Match_Cap: '[6]1) Grid'!$DT$12
Name Pricing_Lkup: '[6]17) Pricing'!$B$9:$HA$1008
Name Print_Area_Reset: OFFSET(Full_Print,0,0,Last_Row)
Name Rev_1: '[6]18) SBS R2 Cash Flow'!$C$17
Name Rev_2: '[6]18) SBS R2 Cash Flow'!$C$18
Name Rev_3: '[6]18) SBS R2 Cash Flow'!$C$19
Name Rev_4: '[6]18) SBS R2 Cash Flow'!$C$20
Name Rev_5: '[6]18) SBS R2 Cash Flow'!$C$21
Name Rev_6: '[6]18) SBS R2 Cash Flow'!$C$22
Name Rev_7: '[6]18) SBS R2 Cash Flow'!$C$23

Sheet Multi Unit Grid
A1: ID | B1: no_data_1 | C1: no_data_2 | D1: data_1 | E1: no_data_3 | F1: no_data_4 | G1: data_2 | H1: data_3
A2: 1 | C2: Firm Name: | D2: Innovate Advisors LLC | E2: *REQUIRED* | F2: Sales Region: | G2: Brooklyn | H2: *REQUIRED* | I2: FY27v1
A3: 2 | C3: Firm Legal Address: | E3: *REQUIRED* | F3: DM Name: | G3: Eli Colman | H3: 0055a00000BGB00AAH
A4: 3 | C4: Firm Contact Name: | D4: Stephen Scialo | F4: SE Name: | G4: Patrick Cassidy | H4: 0055a000006SfQLAA0
A5: 4 | C5: Accounting Firm Phone #: | D5: 845-642-8927 | F5: VP Name: | G5: Shannon Suppa
A6: 5 | C6: Firm Email Address: | D6: sscialo@innovateadvisors.com | F6: ESO Region:
A7: 6 | C7: Current Payroll Platform: | D7: Paychex/Surepayroll | E7: *REQUIRED* | F7: AC Firm ID:
A8: 7 | C8: Firm Saleforce Account Link: | D8: https://myadp.lightning.force.com/lightning/r/Account/001gb00000DD6o8AAD/view | E8: *REQUIRED* | F8: PTA Pic Code: | G8: PW58056
A9: 8 | C9: Salesforce Acquisition ID: | F9: Grid Date: | G9: 46290 | H9: *REQUIRED*
A11: ID | B11: client_count | C11: client_code | D11: ee | E11: payroll_freq | F11: annual_billing | G11: fees | H11: notes
A12: 0 | B12: Client Count | C12: Client Code | D12: Avg # of EEs paid each payroll | E12: Payroll Frequency (1,4,12,24,26,52) | F12: Total Current Annualized Billings (Excluding Year End/W2 Fees) | G12: Year End W2 & 1099 Fees (if no additional fee, type in "Included") | H12: Additional Notes
A13: 1 | B13: 1 | C13: Upstate Logistics Group LLC | D13: 3 | E13: 26 | F13: 2042.82 | G13: Included | H13: Paychex
A14: 2 | B14: 2 | C14: Tyree Advisory Group LLC | D14: 1 | E14: 12 | F14: 863.04 | G14: Included | H14: Paychex
A15: 3 | B15: 3 | C15: RJC Holdings | D15: 1 | E15: 12 | F15: 696 | G15: Included | H15: Paychex - prior ADP client - Paychex cannot link Partner Pro access
A16: 4 | B16: 4 | C16: Kranz Motorcars LLC | D16: 1 | E16: 52 | F16: 3094 | G16: Included | H16: Paychex
A17: 5 | B17: 5 | C17: Wisdom by Woods LLC | D17: 1 | E17: 12 | F17: 1557.36 | G17: Included | H17: Paychex
A18: 6 | B18: 6 | C18: Auction Time Pieces | D18: 2 | E18: 24 | F18: 3698.4 | G18: Included | H18: Paychex
A19: 7 | B19: 7 | C19: Onchain Strategies LLC | D19: 1 | E19: 12 | F19: 1212 | G19: Included | H19: Paychex
A20: 8 | B20: 8 | C20: Backfin Logistics LLC | D20: 3 | E20: 24 | F20: 2364 | G20: Included | H20: Paychex
A21: 9 | B21: 9 | C21: Walters Mirrors Inc | D21: 3 | E21: 26 | F21: 6810.7 | G21: Included | H21: Paychex
A22: 10 | B22: 10 | C22: Spencer Thwaytes & Co LLC | D22: 3 | E22: 12 | F22: 924 | G22: Included | H22: Paychex
A23: 11 | B23: 11 | C23: Complete Merchant Services Consulting | D23: 2 | E23: 12 | F23: 1200 | G23: Included | H23: Gusto - not a Paychex account
A24: 12 | B24: 12 | C24: FRG Advisory LLC | D24: 1 | E24: 12 | F24: 600 | G24: Included | H24: Gusto - not a Paychex account
A25: 13 | B25: 13 | C25: Broadway 2000 Inc | D25: 1 | E25: 1 | F25: 400 | G25: Included | H25: No provider - pays IRS directly via EFTPS - cash payroll
A26: 14 | B26: 14
A27: 15 | B27: 15
A28: 16 | B28: 16
A29: 17 | B29: 17
A30: 18 | B30: 18
A31: 19 | B31: 19
A32: 20 | B32: 20
A33: 21 | B33: 21
A34: 22 | B34: 22
A35: 23 | B35: 23
A36: 24 | B36: 24
A37: 25 | B37: 25
... A113: 101 | B113: 101
B114: 102
B115: 103
B116: 104
...

Sheet Product Selections
I1: no_data | J1: header | K1: data
C2: Firm Legal Name: | D2: ='Multi Unit Grid'!D2 | J2: Contract #: | K2: 05539 | M2: Conversion Agreement Effective Date:
C3: Firm Legal Address: | D3: ='Multi Unit Grid'!D3 | J3: Sales Region: | K3: =IF('Multi Unit Grid'!G2="","",'Multi Unit Grid'!G2) | M3: =IF(L11="Management Services","Conversion Period:","Final Sales Order Signature Date:") | N3: =IF(N2="","",IF(L11="Management Services",N2+(30.4*13),IF(OR(L11="CBA Lightning",L11="CBA Lightning Plus",L11="CBA Lightning Wholesale"),N2+45,"")))
C4: Firm Contact Name: | D4: ='Multi Unit Grid'!D4 | J4: RUN Zone: | K4: =IFERROR(VLOOKUP(K3,'--'!B3:D326,2,FALSE),"") | M4: =IF(L11="Management Services","","Purchase Price Payment Date:") | N4: =IF(N2="","",IF(L11="CBA Lightning Wholesale",N3+60,IF(L11="Management Services","",N3+90)))
C5: Firm Phone #: | D5: ='Multi Unit Grid'!D5 | J5: DM Name: | K5: =IF('Multi Unit Grid'!G3="","",'Multi Unit Grid'!G3)
C6: Firm Email Address: | D6: ='Multi Unit Grid'!D6 | J6: ESO Region: | K6: =IF('Multi Unit Grid'!G6="","",'Multi Unit Grid'!G6)
J7: Current Payroll Provider: | K7: =IF('Multi Unit Grid'!D7="","",'Multi Unit Grid'!D7) | M7: =IF(L11="CBA Lightning","",IF(L11="CBA Lightning Wholesale","",IF(L11="CBA Lightning Plus","","First Payment Date:"))) | N7: =IF(N2="","",IF(L11="CBA Lightning","",IF(L11="CBA Lightning Plus","",IF(L11="CBA Lightning Wholesale","",N2+14))))
J8: AC Firm ID: | K8: =IF('Multi Unit Grid'!G7="","",'Multi Unit Grid'!G7) | M8: =IF(L11="CBA Lightning","",IF(L11="CBA Lightning Wholesale","",IF(L11="CBA Lightning Plus","","Second Payment Date:"))) | N8: =IF(N2="","",IF(L11="CBA Lightning","",IF(L11="CBA Lightning Plus","",IF(L11="CBA Lightning Wholesale","",N2+195))))
J9: PTA PIC Code: | K9: =IF('Multi Unit Grid'!G8="","",'Multi Unit Grid'!G8) | M9: =IF(L11="CBA Lightning","",IF(L11="CBA Lightning Wholesale","",IF(L11="CBA Lightning Plus","","Third Payment Date:"))) | N9: =IF(N2="","",IF(L11="CBA Lightning","",IF(L11="CBA Lightning Plus","",IF(L11="CBA Lightning Wholesale","",N2+440))))
J10: Implementation Region & Branch: | K10: =IFERROR(IF(K3="","",VLOOKUP(K3,Regions!A:B,2,FALSE)),"") | L10: Enter Branch Code
K11: Select CBA Program | L11: CBA Lightning
K12: Multiple: | L12: =IF(L11="CBA Lightning",2,IF(L11="CBA Lightning Plus","Enter Amount",IF(L11="CBA Lightning Wholesale",2,IF(L11="Management Services","TBD","")))) | M12: =IF(L11="CBA Lightning","* The Multiple may be increased as set forth in Attachment 1 of the CBA Lightning Contract.","")
D13: ***Company Legal Name is Required, if left blank contract | G13: 0 | H13: annual_recurring_revenue | S13: ='Exhibit A'!V7
B14: **All information is strictly confidential | D14: will be rejected*** | E14: =SUM(E16:E965) | G14: =SUM(G16:G965) | H14: =SUM(H16:H965) | I14: =SUM(I16:I965) | K14: RUN Payroll Bundle (Type in Yes to select a bundle) | O14: Workers Comp | P14: Timekeeping (PM Only) | S14: =IFERROR('Exhibit A'!V8,"") | U14: ADP RUN Bundle (Will be Hidden)
B15: Client Count | C15: Client Code | D15: Company Legal Name as reflected on 941 ***Letters, numbers, ampersands (&), hypens only (-). No extra spaces*** | E15: Avg # of EEs paid each payroll | F15: Payroll Frequency | G15: Total Current Annualized Billings (Excluding Year End/W2 Fees) @ Above Discount | H15: Total Current Annualized Billings (Excluding Year End/W2 Fees) | I15: Year End W2 & 1099 Fees (if no additional fee, type in "Included") | K15: ADP Essential Payroll | L15: ADP Enhanced Payroll | M15: ADP Complete Payroll and HR Plus | N15: ADP HR Pro (Minimum of 5 Pays) | O15: Pay by Pay | P15: Timekeeping Plus **Not Applicable on CBA Lightning or CBA Lightning Wholesale | Q15: # of Kiosk Tablet Purchase **Not Applicable on CBA Lightning or CBA Lightning Wholesale | S15: ='Exhibit A'!V10 | U15: =IF(C16="","",IF(F16=1,"ADP Essential Payroll",IF(N16="Yes","ADP HR Pro",IF(M16="Yes","ADP Complete Payroll and HR Plus",IF(L16="Yes","ADP Enhanced Payroll",IF(K16="Yes","ADP Essential Payroll","ADP Essential Payroll"))))))
B16: 1 | C16: =IF('Multi Unit Grid'!C13="","",'Multi Unit Grid'!C13) | D16: Upstate Logistics Group LLC | E16: =IFERROR(VLOOKUP(C16,'Multi Unit Grid'!C:D,2,FALSE),"") | F16: =IFERROR(VLOOKUP(C16,'Multi Unit Grid'!C:E,3,FALSE),"") | G16: ='Exhibit A'!Z11*(1-'Product Selections'!$G$13) | H16: =IFERROR(VLOOKUP(C16,'Multi Unit Grid'!C:F,4,FALSE),"") | I16: =IFERROR(VLOOKUP(C16,'Multi Unit Grid'!C:G,5,FALSE),"") | K16: =IF(C16="","",IF($L$11="Management Services","",IF(H16>0,"Yes",IF(L16="Yes","",IF(M16="Yes","",""))))) | L16: Yes | S16: ='Exhibit A'!V11 | U16: =IF(C17="","",IF(F17=1,"ADP Essential Payroll",IF(N17="Yes","ADP HR Pro",IF(M17="Yes","ADP Complete Payroll and HR Plus",IF(L17="Yes","ADP Enhanced Payroll",IF(K17="Yes","ADP Essential Payroll","ADP Essential Payroll"))))))
B17: =B16+1 | C17: =IF('Multi Unit Grid'!C14="","",'Multi Unit Grid'!C14) | D17: Tyree Advisory Group LLC | E17: =IFERROR(VLOOKUP(C17,'Multi Unit Grid'!C:D,2,FALSE),"") | F17: =IFERROR(VLOOKUP(C17,'Multi Unit Grid'!C:E,3,FALSE),"") | G17: ='Exhibit A'!Z12*(1-'Product Selections'!$G$13) | H17: =IFERROR(VLOOKUP(C17,'Multi Unit Grid'!C:F,4,FALSE),"") | I17: =IFERROR(VLOOKUP(C17,'Multi Unit Grid'!C:G,5,FALSE),"") | K17: =IF(C17="","",IF($L$11="Management Services","",IF(H17>0,"Yes",IF(L17="Yes","",IF(M17="Yes","",""))))) | L17: Yes | S17: ='Exhibit A'!V12 | U17: =IF(C18="","",IF(F18=1,"ADP Essential Payroll",IF(N18="Yes","ADP HR Pro",IF(M18="Yes","ADP Complete Payroll and HR Plus",IF(L18="Yes","ADP Enhanced Payroll",IF(K18="Yes","ADP Essential Payroll","ADP Essential Payroll"))))))
B18: =B17+1 | C18: =IF('Multi Unit Grid'!C15="","",'Multi Unit Grid'!C15) | D18: RJC Holdings | E18: =IFERROR(VLOOKUP(C18,'Multi Unit Grid'!C:D,2,FALSE),"") | F18: =IFERROR(VLOOKUP(C18,'Multi Unit Grid'!C:E,3,FALSE),"") | G18: ='Exhibit A'!Z13*(1-'Product Selections'!$G$13) | H18: =IFERROR(VLOOKUP(C18,'Multi Unit Grid'!C:F,4,FALSE),"") | I18: =IFERROR(VLOOKUP(C18,'Multi Unit Grid'!C:G,5,FALSE),"") | K18: =IF(C18="","",IF($L$11="Management Services","",IF(H18>0,"Yes",IF(L18="Yes","",IF(M18="Yes","",""))))) | L18: Yes | S18: ='Exhibit A'!V13 | U18: =IF(C19="","",IF(F19=1,"ADP Essential Payroll",IF(N19="Yes","ADP HR Pro",IF(M19="Yes","ADP Complete Payroll and HR Plus",IF(L19="Yes","ADP Enhanced Payroll",IF(K19="Yes","ADP Essential Payroll","ADP Essential Payroll"))))))
B19: =B18+1 | C19: =IF('Multi Unit Grid'!C16="","",'Multi Unit Grid'!C16) | D19: Kranz Motorcars LLC | E19: =IFERROR(VLOOKUP(C19,'Multi Unit Grid'!C:D,2,FALSE),"") | F19: =IFERROR(VLOOKUP(C19,'Multi Unit Grid'!C:E,3,FALSE),"") | G19: ='Exhibit A'!Z14*(1-'Product Selections'!$G$13) | H19: =IFERROR(VLOOKUP(C19,'Multi Unit Grid'!C:F,4,FALSE),"") | I19: =IFERROR(VLOOKUP(C19,'Multi Unit Grid'!C:G,5,FALSE),"") | K19: =IF(C19="","",IF($L$11="Management Services","",IF(H19>0,"Yes",IF(L19="Yes","",IF(M19="Yes","",""))))) | L19: Yes | S19: ='Exhibit A'!V14 | U19: =IF(C20="","",IF(F20=1,"ADP Essential Payroll",IF(N20="Yes","ADP HR Pro",IF(M20="Yes","ADP Complete Payroll and HR Plus",IF(L20="Yes","ADP Enhanced Payroll",IF(K20="Yes","ADP Essential Payroll","ADP Essential Payroll"))))))
B20: =B19+1 | C20: =IF('Multi Unit Grid'!C17="","",'Multi Unit Grid'!C17) | D20: Wisdom by Woods LLC | E20: =IFERROR(VLOOKUP(C20,'Multi Unit Grid'!C:D,2,FALSE),"") | F20: =IFERROR(VLOOKUP(C20,'Multi Unit Grid'!C:E,3,FALSE),"") | G20: ='Exhibit A'!Z15*(1-'Product Selections'!$G$13) | H20: =IFERROR(VLOOKUP(C20,'Multi Unit Grid'!C:F,4,FALSE),"") | I20: =IFERROR(VLOOKUP(C20,'Multi Unit Grid'!C:G,5,FALSE),"") | K20: =IF(C20="","",IF($L$11="Management Services","",IF(H20>0,"Yes",IF(L20="Yes","",IF(M20="Yes","",""))))) | L20: Yes | S20: ='Exhibit A'!V15 | U20: =IF(C21="","",IF(F21=1,"ADP Essential Payroll",IF(N21="Yes","ADP HR Pro",IF(M21="Yes","ADP Complete Payroll and HR Plus",IF(L21="Yes","ADP Enhanced Payroll",IF(K21="Yes","ADP Essential Payroll","ADP Essential Payroll"))))))
B21: =B20+1 | C21: =IF('Multi Unit Grid'!C18="","",'Multi Unit Grid'!C18) | D21: Auction Time Pieces | E21: =IFERROR(VLOOKUP(C21,'Multi Unit Grid'!C:D,2,FALSE),"") | F21: =IFERROR(VLOOKUP(C21,'Multi Unit Grid'!C:E,3,FALSE),"") | G21: ='Exhibit A'!Z16*(1-'Product Selections'!$G$13) | H21: =IFERROR(VLOOKUP(C21,'Multi Unit Grid'!C:F,4,FALSE),"") | I21: =IFERROR(VLOOKUP(C21,'Multi Unit Grid'!C:G,5,FALSE),"") | K21: =IF(C21="","",IF($L$11="Management Services","",IF(H21>0,"Yes",IF(L21="Yes","",IF(M21="Yes","",""))))) | M21: Yes | S21: ='Exhibit A'!V16 | U21: =IF(C22="","",IF(F22=1,"ADP Essential Payroll",IF(N22="Yes","ADP HR Pro",IF(M22="Yes","ADP Complete Payroll and HR Plus",IF(L22="Yes","ADP Enhanced Payroll",IF(K22="Yes","ADP Essential Payroll","ADP Essential Payroll"))))))
B22: =B21+1 | C22: =IF('Multi Unit Grid'!C19="","",'Multi Unit Grid'!C19) | D22: Onchain Strategies LLC | E22: =IFERROR(VLOOKUP(C22,'Multi Unit Grid'!C:D,2,FALSE),"") | F22: =IFERROR(VLOOKUP(C22,'Multi Unit Grid'!C:E,3,FALSE),"") | G22: ='Exhibit A'!Z17*(1-'Product Selections'!$G$13) | H22: =IFERROR(VLOOKUP(C22,'Multi Unit Grid'!C:F,4,FALSE),"") | I22: =IFERROR(VLOOKUP(C22,'Multi Unit Grid'!C:G,5,FALSE),"") | K22: =IF(C22="","",IF($L$11="Management Services","",IF(H22>0,"Yes",IF(L22="Yes","",IF(M22="Yes","",""))))) | L22: Yes | S22: ='Exhibit A'!V17 | U22: =IF(C23="","",IF(F23=1,"ADP Essential Payroll",IF(N23="Yes","ADP HR Pro",IF(M23="Yes","ADP Complete Payroll and HR Plus",IF(L23="Yes","ADP Enhanced Payroll",IF(K23="Yes","ADP Essential Payroll","ADP Essential Payroll"))))))
B23: =B22+1 | C23: =IF('Multi Unit Grid'!C20="","",'Multi Unit Grid'!C20) | D23: Backfin Logistics LLC | E23: =IFERROR(VLOOKUP(C23,'Multi Unit Grid'!C:D,2,FALSE),"") | F23: =IFERROR(VLOOKUP(C23,'Multi Unit Grid'!C:E,3,FALSE),"") | G23: ='Exhibit A'!Z18*(1-'Product Selections'!$G$13) | H23: =IFERROR(VLOOKUP(C23,'Multi Unit Grid'!C:F,4,FALSE),"") | I23: =IFERROR(VLOOKUP(C23,'Multi Unit Grid'!C:G,5,FALSE),"") | K23: =IF(C23="","",IF($L$11="Management Services","",IF(H23>0,"Yes",IF(L23="Yes","",IF(M23="Yes","",""))))) | L23: Yes | S23: ='Exhibit A'!V18 | U23: =IF(C24="","",IF(F24=1,"ADP Essential Payroll",IF(N24="Yes","ADP HR Pro",IF(M24="Yes","ADP Complete Payroll and HR Plus",IF(L24="Yes","ADP Enhanced Payroll",IF(K24="Yes","ADP Essential Payroll","ADP Essential Payroll"))))))
B24: =B23+1 | C24: =IF('Multi Unit Grid'!C21="","",'Multi Unit Grid'!C21) | D24: Walters Mirrors Inc | E24: =IFERROR(VLOOKUP(C24,'Multi Unit Grid'!C:D,2,FALSE),"") | F24: =IFERROR(VLOOKUP(C24,'Multi Unit Grid'!C:E,3,FALSE),"") | G24: ='Exhibit A'!Z19*(1-'Product Selections'!$G$13) | H24: =IFERROR(VLOOKUP(C24,'Multi Unit Grid'!C:F,4,FALSE),"") | I24: =IFERROR(VLOOKUP(C24,'Multi Unit Grid'!C:G,5,FALSE),"") | K24: =IF(C24="","",IF($L$11="Management Services","",IF(H24>0,"Yes",IF(L24="Yes","",IF(M24="Yes","",""))))) | N24: Yes | S24: ='Exhibit A'!V19 | U24: =IF(C25="","",IF(F25=1,"ADP Essential Payroll",IF(N25="Yes","ADP HR Pro",IF(M25="Yes","ADP Complete Payroll and HR Plus",IF(L25="Yes","ADP Enhanced Payroll",IF(K25="Yes","ADP Essential Payroll","ADP Essential Payroll"))))))
B25: =B24+1 | C25: =IF('Multi Unit Grid'!C22="","",'Multi Unit Grid'!C22) | D25: Spencer Thwaytes & Co LLC | E25: =IFERROR(VLOOKUP(C25,'Multi Unit Grid'!C:D,2,FALSE),"") | F25: =IFERROR(VLOOKUP(C25,'Multi Unit Grid'!C:E,3,FALSE),"") | G25: ='Exhibit A'!Z20*(1-'Product Selections'!$G$13) | H25: =IFERROR(VLOOKUP(C25,'Multi Unit Grid'!C:F,4,FALSE),"") | I25: =IFERROR(VLOOKUP(C25,'Multi Unit Grid'!C:G,5,FALSE),"") | K25: =IF(C25="","",IF($L$11="Management Services","",IF(H25>0,"Yes",IF(L25="Yes","",IF(M25="Yes","",""))))) | L25: Yes | S25: ='Exhibit A'!V20 | U25: =IF(C26="","",IF(F26=1,"ADP Essential Payroll",IF(N26="Yes","ADP HR Pro",IF(M26="Yes","ADP Complete Payroll and HR Plus",IF(L26="Yes","ADP Enhanced Payroll",IF(K26="Yes","ADP Essential Payroll","ADP Essential Payroll"))))))
B26: =B25+1 | C26: =IF('Multi Unit Grid'!C23="","",'Multi Unit Grid'!C23) | D26: Complete Merchant Services Consulting | E26: =IFERROR(VLOOKUP(C26,'Multi Unit Grid'!C:D,2,FALSE),"") | F26: =IFERROR(VLOOKUP(C26,'Multi Unit Grid'!C:E,3,FALSE),"") | G26: ='Exhibit A'!Z21*(1-'Product Selections'!$G$13) | H26: =IFERROR(VLOOKUP(C26,'Multi Unit Grid'!C:F,4,FALSE),"") | I26: =IFERROR(VLOOKUP(C26,'Multi Unit Grid'!C:G,5,FALSE),"") | K26: =IF(C26="","",IF($L$11="Management Services","",IF(H26>0,"Yes",IF(L26="Yes","",IF(M26="Yes","",""))))) | L26: Yes | S26: ='Exhibit A'!V21 | U26: =IF(C27="","",IF(F27=1,"ADP Essential Payroll",IF(N27="Yes","ADP HR Pro",IF(M27="Yes","ADP Complete Payroll and HR Plus",IF(L27="Yes","ADP Enhanced Payroll",IF(K27="Yes","ADP Essential Payroll","ADP Essential Payroll"))))))
B27: =B26+1 | C27: =IF('Multi Unit Grid'!C24="","",'Multi Unit Grid'!C24) | D27: FRG Advisory LLC | E27: =IFERROR(VLOOKUP(C27,'Multi Unit Grid'!C:D,2,FALSE),"") | F27: =IFERROR(VLOOKUP(C27,'Multi Unit Grid'!C:E,3,FALSE),"") | G27: ='Exhibit A'!Z22*(1-'Product Selections'!$G$13) | H27: =IFERROR(VLOOKUP(C27,'Multi Unit Grid'!C:F,4,FALSE),"") | I27: =IFERROR(VLOOKUP(C27,'Multi Unit Grid'!C:G,5,FALSE),"") | K27: =IF(C27="","",IF($L$11="Management Services","",IF(H27>0,"Yes",IF(L27="Yes","",IF(M27="Yes","",""))))) | L27: Yes | S27: ='Exhibit A'!V22 | U27: =IF(C28="","",IF(F28=1,"ADP Essential Payroll",IF(N28="Yes","ADP HR Pro",IF(M28="Yes","ADP Complete Payroll and HR Plus",IF(L28="Yes","ADP Enhanced Payroll",IF(K28="Yes","ADP Essential Payroll","ADP Essential Payroll"))))))
B28: =B27+1 | C28: =IF('Multi Unit Grid'!C25="","",'Multi Unit Grid'!C25) | D28: Broadway 2000 Inc | E28: =IFERROR(VLOOKUP(C28,'Multi Unit Grid'!C:D,2,FALSE),"") | F28: =IFERROR(VLOOKUP(C28,'Multi Unit Grid'!C:E,3,FALSE),"") | G28: ='Exhibit A'!Z23*(1-'Product Selections'!$G$13) | H28: =IFERROR(VLOOKUP(C28,'Multi Unit Grid'!C:F,4,FALSE),"") | I28: =IFERROR(VLOOKUP(C28,'Multi Unit Grid'!C:G,5,FALSE),"") | K28: =IF(C28="","",IF($L$11="Management Services","",IF(H28>0,"Yes",IF(L28="Yes","",IF(M28="Yes","",""))))) | L28: Yes | S28: ='Exhibit A'!V23 | U28: =IF(C29="","",IF(F29=1,"ADP Essential Payroll",IF(N29="Yes","ADP HR Pro",IF(M29="Yes","ADP Complete Payroll and HR Plus",IF(L29="Yes","ADP Enhanced Payroll",IF(K29="Yes","ADP Essential Payroll","ADP Essential Payroll"))))))
B29: =B28+1 | C29: =IF('Multi Unit Grid'!C26="","",'Multi Unit Grid'!C26) | E29: =IFERROR(VLOOKUP(C29,'Multi Unit Grid'!C:D,2,FALSE),"") | F29: =IFERROR(VLOOKUP(C29,'Multi Unit Grid'!C:E,3,FALSE),"") | G29: ='Exhibit A'!Z24*(1-'Product Selections'!$G$13) | H29: =IFERROR(VLOOKUP(C29,'Multi Unit Grid'!C:F,4,FALSE),"") | I29: =IFERROR(VLOOKUP(C29,'Multi Unit Grid'!C:G,5,FALSE),"") | K29: =IF(C29="","",IF($L$11="Management Services","",IF(H29>0,"Yes",IF(L29="Yes","",IF(M29="Yes","",""))))) | S29: ='Exhibit A'!V24 | U29: =IF(C30="","",IF(F30=1,"ADP Essential Payroll",IF(N30="Yes","ADP HR Pro",IF(M30="Yes","ADP Complete Payroll and HR Plus",IF(L30="Yes","ADP Enhanced Payroll",IF(K30="Yes","ADP Essential Payroll","ADP Essential Payroll"))))))
B30: =B29+1 | C30: =IF('Multi Unit Grid'!C27="","",'Multi Unit Grid'!C27) | E30: =IFERROR(VLOOKUP(C30,'Multi Unit Grid'!C:D,2,FALSE),"") | F30: =IFERROR(VLOOKUP(C30,'Multi Unit Grid'!C:E,3,FALSE),"") | G30: ='Exhibit A'!Z25*(1-'Product Selections'!$G$13) | H30: =IFERROR(VLOOKUP(C30,'Multi Unit Grid'!C:F,4,FALSE),"") | I30: =IFERROR(VLOOKUP(C30,'Multi Unit Grid'!C:G,5,FALSE),"") | K30: =IF(C30="","",IF($L$11="Management Services","",IF(H30>0,"Yes",IF(L30="Yes","",IF(M30="Yes","",""))))) | S30: ='Exhibit A'!V25 | U30: =IF(C31="","",IF(F31=1,"ADP Essential Payroll",IF(N31="Yes","ADP HR Pro",IF(M31="Yes","ADP Complete Payroll and HR Plus",IF(L31="Yes","ADP Enhanced Payroll",IF(K31="Yes","ADP Essential Payroll","ADP Essential Payroll"))))))
B31: =B30+1 | C31: =IF('Multi Unit Grid'!C28="","",'Multi Unit Grid'!C28) | E31: =IFERROR(VLOOKUP(C31,'Multi Unit Grid'!C:D,2,FALSE),"") | F31: =IFERROR(VLOOKUP(C31,'Multi Unit Grid'!C:E,3,FALSE),"") | G31: ='Exhibit A'!Z26*(1-'Product Selections'!$G$13) | H31: =IFERROR(VLOOKUP(C31,'Multi Unit Grid'!C:F,4,FALSE),"") | I31: =IFERROR(VLOOKUP(C31,'Multi Unit Grid'!C:G,5,FALSE),"") | K31: =IF(C31="","",IF($L$11="Management Services","",IF(H31>0,"Yes",IF(L31="Yes","",IF(M31="Yes","",""))))) | S31: ='Exhibit A'!V26 | U31: =IF(C32="","",IF(F32=1,"ADP Essential Payroll",IF(N32="Yes","ADP HR Pro",IF(M32="Yes","ADP Complete Payroll and HR Plus",IF(L32="Yes","ADP Enhanced Payroll",IF(K32="Yes","ADP Essential Payroll","ADP Essential Payroll"))))))
B32: =B31+1 | C32: =IF('Multi Unit Grid'!C29="","",'Multi Unit Grid'!C29) | E32: =IFERROR(VLOOKUP(C32,'Multi Unit Grid'!C:D,2,FALSE),"") | F32: =IFERROR(VLOOKUP(C32,'Multi Unit Grid'!C:E,3,FALSE),"") | G32: ='Exhibit A'!Z27*(1-'Product Selections'!$G$13) | H32: =IFERROR(VLOOKUP(C32,'Multi Unit Grid'!C:F,4,FALSE),"") | I32: =IFERROR(VLOOKUP(C32,'Multi Unit Grid'!C:G,5,FALSE),"") | K32: =IF(C32="","",IF($L$11="Management Services","",IF(H32>0,"Yes",IF(L32="Yes","",IF(M32="Yes","",""))))) | S32: ='Exhibit A'!V27 | U32: =IF(C33="","",IF(F33=1,"ADP Essential Payroll",IF(N33="Yes","ADP HR Pro",IF(M33="Yes","ADP Complete Payroll and HR Plus",IF(L33="Yes","ADP Enhanced Payroll",IF(K33="Yes","ADP Essential Payroll","ADP Essential Payroll"))))))
B33: =B32+1 | C33: =IF('Multi Unit Grid'!C30="","",'Multi Unit Grid'!C30) | E33: =IFERROR(VLOOKUP(C33,'Multi Unit Grid'!C:D,2,FALSE),"") | F33: =IFERROR(VLOOKUP(C33,'Multi Unit Grid'!C:E,3,FALSE),"") | G33: ='Exhibit A'!Z28*(1-'Product Selections'!$G$13) | H33: =IFERROR(VLOOKUP(C33,'Multi Unit Grid'!C:F,4,FALSE),"") | I33: =IFERROR(VLOOKUP(C33,'Multi Unit Grid'!C:G,5,FALSE),"") | K33: =IF(C33="","",IF($L$11="Management Services","",IF(H33>0,"Yes",IF(L33="Yes","",IF(M33="Yes","",""))))) | S33: ='Exhibit A'!V28 | U33: =IF(C34="","",IF(F34=1,"ADP Essential Payroll",IF(N34="Yes","ADP HR Pro",IF(M34="Yes","ADP Complete Payroll and HR Plus",IF(L34="Yes","ADP Enhanced Payroll",IF(K34="Yes","ADP Essential Payroll","ADP Essential Payroll"))))))
B34: =B33+1 | C34: =IF('Multi Unit Grid'!C31="","",'Multi Unit Grid'!C31) | E34: =IFERROR(VLOOKUP(C34,'Multi Unit Grid'!C:D,2,FALSE),"") | F34: =IFERROR(VLOOKUP(C34,'Multi Unit Grid'!C:E,3,FALSE),"") | G34: ='Exhibit A'!Z29*(1-'Product Selections'!$G$13) | H34: =IFERROR(VLOOKUP(C34,'Multi Unit Grid'!C:F,4,FALSE),"") | I34: =IFERROR(VLOOKUP(C34,'Multi Unit Grid'!C:G,5,FALSE),"") | K34: =IF(C34="","",IF($L$11="Management Services","",IF(H34>0,"Yes",IF(L34="Yes","",IF(M34="Yes","",""))))) | S34: ='Exhibit A'!V29 | U34: =IF(C35="","",IF(F35=1,"ADP Essential Payroll",IF(N35="Yes","ADP HR Pro",IF(M35="Yes","ADP Complete Payroll and HR Plus",IF(L35="Yes","ADP Enhanced Payroll",IF(K35="Yes","ADP Essential Payroll","ADP Essential Payroll"))))))
B35: =B34+1 | C35: =IF('Multi Unit Grid'!C32="","",'Multi Unit Grid'!C32) | E35: =IFERROR(VLOOKUP(C35,'Multi Unit Grid'!C:D,2,FALSE),"") | F35: =IFERROR(VLOOKUP(C35,'Multi Unit Grid'!C:E,3,FALSE),"") | G35: ='Exhibit A'!Z30*(1-'Product Selections'!$G$13) | H35: =IFERROR(VLOOKUP(C35,'Multi Unit Grid'!C:F,4,FALSE),"") | I35: =IFERROR(VLOOKUP(C35,'Multi Unit Grid'!C:G,5,FALSE),"") | K35: =IF(C35="","",IF($L$11="Management Services","",IF(H35>0,"Yes",IF(L35="Yes","",IF(M35="Yes","",""))))) | S35: ='Exhibit A'!V30 | U35: =IF(C36="","",IF(F36=1,"ADP Essential Payroll",IF(N36="Yes","ADP HR Pro",IF(M36="Yes","ADP Complete Payroll and HR Plus",IF(L36="Yes","ADP Enhanced Payroll",IF(K36="Yes","ADP Essential Payroll","ADP Essential Payroll"))))))
B36: =B35+1 | C36: =IF('Multi Unit Grid'!C33="","",'Multi Unit Grid'!C33) | E36: =IFERROR(VLOOKUP(C36,'Multi Unit Grid'!C:D,2,FALSE),"") | F36: =IFERROR(VLOOKUP(C36,'Multi Unit Grid'!C:E,3,FALSE),"") | G36: ='Exhibit A'!Z31*(1-'Product Selections'!$G$13) | H36: =IFERROR(VLOOKUP(C36,'Multi Unit Grid'!C:F,4,FALSE),"") | I36: =IFERROR(VLOOKUP(C36,'Multi Unit Grid'!C:G,5,FALSE),"") | K36: =IF(C36="","",IF($L$11="Management Services","",IF(H36>0,"Yes",IF(L36="Yes","",IF(M36="Yes","",""))))) | S36: ='Exhibit A'!V31 | U36: =IF(C37="","",IF(F37=1,"ADP Essential Payroll",IF(N37="Yes","ADP HR Pro",IF(M37="Yes","ADP Complete Payroll and HR Plus",IF(L37="Yes","ADP Enhanced Payroll",IF(K37="Yes","ADP Essential Payroll","ADP Essential Payroll"))))))
B37: =B36+1 | C37: =IF('Multi Unit Grid'!C34="","",'Multi Unit Grid'!C34) | E37: =IFERROR(VLOOKUP(C37,'Multi Unit Grid'!C:D,2,FALSE),"") | F37: =IFERROR(VLOOKUP(C37,'Multi Unit Grid'!C:E,3,FALSE),"") | G37: ='Exhibit A'!Z32*(1-'Product Selections'!$G$13) | H37: =IFERROR(VLOOKUP(C37,'Multi Unit Grid'!C:F,4,FALSE),"") | I37: =IFERROR(VLOOKUP(C37,'Multi Unit Grid'!C:G,5,FALSE),"") | K37: =IF(C37="","",IF($L$11="Management Services","",IF(H37>0,"Yes",IF(L37="Yes","",IF(M37="Yes","",""))))) | S37: ='Exhibit A'!V32 | U37: =IF(C38="","",IF(F38=1,"ADP Essential Payroll",IF(N38="Yes","ADP HR Pro",IF(M38="Yes","ADP Complete Payroll and HR Plus",IF(L38="Yes","ADP Enhanced Payroll",IF(K38="Yes","ADP Essential Payroll","ADP Essential Payroll"))))))
B38: =B37+1 | C38: =IF('Multi Unit Grid'!C35="","",'Multi Unit Grid'!C35) | E38: =IFERROR(VLOOKUP(C38,'Multi Unit Grid'!C:D,2,FALSE),"") | F38: =IFERROR(VLOOKUP(C38,'Multi Unit Grid'!C:E,3,FALSE),"") | G38: ='Exhibit A'!Z33*(1-'Product Selections'!$G$13) | H38: =IFERROR(VLOOKUP(C38,'Multi Unit Grid'!C:F,4,FALSE),"") | I38: =IFERROR(VLOOKUP(C38,'Multi Unit Grid'!C:G,5,FALSE),"") | K38: =IF(C38="","",IF($L$11="Management Services","",IF(H38>0,"Yes",IF(L38="Yes","",IF(M38="Yes","",""))))) | S38: ='Exhibit A'!V33 | U38: =IF(C39="","",IF(F39=1,"ADP Essential Payroll",IF(N39="Yes","ADP HR Pro",IF(M39="Yes","ADP Complete Payroll and HR Plus",IF(L39="Yes","ADP Enhanced Payroll",IF(K39="Yes","ADP Essential Payroll","ADP Essential Payroll"))))))
B39: =B38+1 | C39: =IF('Multi Unit Grid'!C36="","",'Multi Unit Grid'!C36) | E39: =IFERROR(VLOOKUP(C39,'Multi Unit Grid'!C:D,2,FALSE),"") | F39: =IFERROR(VLOOKUP(C39,'Multi Unit Grid'!C:E,3,FALSE),"") | G39: ='Exhibit A'!Z34*(1-'Product Selections'!$G$13) | H39: =IFERROR(VLOOKUP(C39,'Multi Unit Grid'!C:F,4,FALSE),"") | I39: =IFERROR(VLOOKUP(C39,'Multi Unit Grid'!C:G,5,FALSE),"") | K39: =IF(C39="","",IF($L$11="Management Services","",IF(H39>0,"Yes",IF(L39="Yes","",IF(M39="Yes","",""))))) | S39: ='Exhibit A'!V34 | U39: =IF(C40="","",IF(F40=1,"ADP Essential Payroll",IF(N40="Yes","ADP HR Pro",IF(M40="Yes","ADP Complete Payroll and HR Plus",IF(L40="Yes","ADP Enhanced Payroll",IF(K40="Yes","ADP Essential Payroll","ADP Essential Payroll"))))))
B40: =B39+1 | C40: =IF('Multi Unit Grid'!C37="","",'Multi Unit Grid'!C37) | E40: =IFERROR(VLOOKUP(C40,'Multi Unit Grid'!C:D,2,FALSE),"") | F40: =IFERROR(VLOOKUP(C40,'Multi Unit Grid'!C:E,3,FALSE),"") | G40: ='Exhibit A'!Z35*(1-'Product Selections'!$G$13) | H40: =IFERROR(VLOOKUP(C40,'Multi Unit Grid'!C:F,4,FALSE),"") | I40: =IFERROR(VLOOKUP(C40,'Multi Unit Grid'!C:G,5,FALSE),"") | K40: =IF(C40="","",IF($L$11="Management Services","",IF(H40>0,"Yes",IF(L40="Yes","",IF(M40="Yes","",""))))) | S40: ='Exhibit A'!V35 | U40: =IF(C41="","",IF(F41=1,"ADP Essential Payroll",IF(N41="Yes","ADP HR Pro",IF(M41="Yes","ADP Complete Payroll and HR Plus",IF(L41="Yes","ADP Enhanced Payroll",IF(K41="Yes","ADP Essential Payroll","ADP Essential Payroll"))))))
...

Sheet Exhibit A
C2: Firm's Legal Name: | D2: ='Product Selections'!D2 | N2: Conversion Agreement Effective Date: | O2: ='Product Selections'!N2 | P2: Exhibit A
C3: Firm's Legal Address: | D3: ='Product Selections'!D3 | N3: =IF(J11="Management Services","Conversion Period:","Final Sales Order Signature Date:") | O3: ='Product Selections'!N3 | P3: ='Product Selections'!J2&" "&'Product Selections'!K2
N4: =IF(J11="Management Services","","Purchase Price Payment Date:") | O4: ='Product Selections'!N4 | P4: ='Product Selections'!L11
C5: Seller's Signature: | G5: Sales VP Signature: | P5: =IF('Product Selections'!L11="Management Services","",IF('Product Selections'!L11="CBA Lightning Plus","2.50",'Product Selections'!K12&'Product Selections'!L12&".0"))
P6: =IF(P4="CBA Lightning","* The Multiple may be increased as set forth in Attachment 1 of the CBA Lightning Contract.","")
B7: *ADP, Inc. is relying on this information for valuation and client conversion. Please ensure complete accuracy on all data provided as incorrect data may result in post conversion revaluation. | K7: =IF('Product Selections'!L11="","",IF('Product Selections'!L11="Management Services","",K9*'Product Selections'!L12)) | L7: Estimated Payout at 100% Conversion | V7: ADP W2 Pricing:
B8: **All information is strictly confidential | H8: Seller's Grid Revenue | K8: Included In CBA Payment | O8: Excluded From CBA Payment | R8: Internal Sales Resource for ESO Pricing | V8: =IFERROR(IF(I9/SUM(AA11:AA960)<=1,"50% ADP Discount","ADP Book Price"),"") | Y8: =IFERROR(H9/Z8,"") | Z8: =SUM(Z11:Z960) | AA8: =SUM(AA11:AA960) | AB8: =SUM(AB11:AB960) | AC8: =SUM(AC11:AC960) | AD8: =SUM(AD11:AD960)
B9: =COUNT(H11:H960) | D9: Total | E9: =SUM(E11:E960) | H9: =SUM(H11:H960) | I9: ='Product Selections'!I14 | K9: =SUM(K11:K960) | L9: =SUM(L11:L960) | M9: =SUM(M11:M960) | O9: =SUM(O11:O960) | P9: =SUM(P11:P960) | R9: =SUM(R11:R960) | S9: =SUM(S11:S960) | T9: =SUM(T11:T960) | X9: Internal Use Only | Z9: Book Price | AE9: =SUM(AE11:AE960)
B10: Client Count | C10: Client Code | D10: Company Legal Name | E10: Avg # of EEs paid each payroll | F10: Payroll Frequency | G10: ADP Payroll Bundle Assigned | H10: Total Current Annualized Billings (Excl. W2 Fees) | I10: Year End W2 & 1099 Fees | K10: Total ADP Annual Revenue | L10: ADP Annual Time Revenue | M10: ADP Annual Workers Compensation Pay by Pay Revenue | O10: Revenue Exceeding ADP Book Pricing | P10: ="W2 Fees ("& V8&")" | R10: Payroll Per Processing Fee | S10: Estimated SBS Timekeeping Plus Processing Fee (Match RUN Discount) | T10: Workers Comp Per Processing Fee | V10: DM Note | X10: Note | Y10: RUN Payroll ProcessingDiscount % | Z10: RUN Payroll | AA10: W2 | AB10: WC Pay by Pay | AC10: ADP Timekeeping Plus | AD10: Kiosk Tablet (Purchase) | AE10: ADP Annual Payroll Processing Revenue* | AG10: Multiple | AH10: Note
B11: =IF('Product Selections'!B16="","",'Product Selections'!B16) | C11: =IF('Product Selections'!C16="","",'Product Selections'!C16) | D11: =IF('Product Selections'!D16="","",'Product Selections'!D16) | E11: =IF('Product Selections'!E16="","",'Product Selections'!E16) | F11: =IF('Product Selections'!F16="","",'Product Selections'!F16) | G11: =IF('Product Selections'!U15="","",'Product Selections'!U15) | H11: =IF('Product Selections'!H16="","",'Product Selections'!H16) | I11: =IFERROR(IF(TRIM('Product Selections'!I16)="","",TRIM('Product Selections'!I16)),"") | K11: =IF(C11="","",IF(O11="",AE11+L11+M11,AE11+L11+M11+O11)) | L11: =IF(C11="","",SUM(AC11,AD11)*(1-Y11)) | M11: =IF(C11="","",AB11) | O11: =IF(C11="","",IF(Y11<0,Z11-AE11,"")) | P11: =IFERROR(IF(C11="","",IF(AND(C11=$D$2,H11=0),0,IF($V$8="50% ADP Discount",AA11*0.5,IF($V$8="ADP Book Price",AA11)))),"") | R11: =IF(C11="","",IF(Y11<0,(Z11/F11)*(1),(Z11/F11)*(1-Y11))) | S11: =IFERROR(IF(Y11<0,SUM(AC11:AD11)/F11,L11/F11),"") | T11: =IF(M11="","",IF(M11=0,"",SUM(M11)/F11)) | V11: =IF(C11="","",IF(AND(C11=$D$2,H11=0),"Firm Payroll",IF(AND(F11=1,Y11>0.2),"Annual 20% Max Discount",IF(AND(F11=4,Y11>0.2),"Quarterly 20% Max Discount",IF(Y11>=0.6,"Discount >60%",IF(Y11<0,"Revenue Reduction Required","")))))) | X11: =IF(F11=1,"Annual Payrolls on ADP Essential Payroll",IF(F11=4,"Quarterly Payrolls on ADP Essential Payroll","")) | Y11: =IFERROR(1-((H11-M11)/SUM(Z11,AC11,AD11)),"") | Z11: =IF($C11="","",HLOOKUP($G11&'Product Selections'!$K$4&'Exhibit A'!$F11,'--'!$F$3:$AT$200,$E11+6,FALSE)*$F11) | AA11: =IF($C11="","",7.95*$E11+54.95) | AB11: =IF('Product Selections'!O16="Yes",16*'Exhibit A'!F11,0) | AC11: =IF('Product Selections'!$L$11="CBA Lightning Wholesale",0,IF('Product Selections'!$L$11="CBA Lightning",0,IF($C11="",0,IF('Product Selections'!P16="",0,IF('Product Selections'!$P16="Yes",HLOOKUP($AC$10&'Exhibit A'!$F11,'--'!$F$3:$AZ$200,$E11+6,FALSE)*$F11))))) | AD11: =IF('Product Selections'!$L$11="CBA Lightning Wholesale",0,IF('Product Selections'!$L$11="CBA Lightning",0,IF('Product Selections'!Q16="",0,IF($C11="",0,IF('Product Selections'!$Q16>=0,HLOOKUP($AD$10,'--'!$F$3:$AZ$200,3,FALSE)*12*'Product Selections'!Q16))))) | AE11: =IFERROR(IF(C11="","",IF(AND(C11=$D$2,H11=0),0,IF(I11=0,H11-P11-L11-M11,IF(I11="Included",H11-P11-M11-L11,IF(I11>0,H11-M11-L11))))),"") | AG11: 0.7 | AH11: ="Estimated Payout at 100% conversion ["&AG11&"0 multiple * Annual Payroll Processing Revenue with Revenue Reduction]"
B12: =IFERROR(IF('Product Selections'!B17="","",'Product Selections'!B17),"") | C12: =IF('Product Selections'!C17="","",'Product Selections'!C17) | D12: =IF('Product Selections'!D17="","",'Product Selections'!D17) | E12: =IF('Product Selections'!E17="","",'Product Selections'!E17) | F12: =IF('Product Selections'!F17="","",'Product Selections'!F17) | G12: =IF('Product Selections'!U16="","",'Product Selections'!U16) | H12: =IFERROR(IF('Product Selections'!H17="","",'Product Selections'!H17),"") | I12: =IFERROR(IF(TRIM('Product Selections'!I17)="","",TRIM('Product Selections'!I17)),"") | K12: =IF(C12="","",IF(O12="",AE12+L12+M12,AE12+L12+M12+O12)) | L12: =IF(C12="","",SUM(AC12,AD12)*(1-Y12)) | M12: =IF(C12="","",AB12) | O12: =IF(C12="","",IF(Y12<0,Z12-AE12,"")) | P12: =IFERROR(IF(C12="","",IF(AND(C12=$D$2,H12=0),0,IF($V$8="50% ADP Discount",AA12*0.5,IF($V$8="ADP Book Price",AA12)))),"") | R12: =IF(C12="","",IF(Y12<0,(Z12/F12)*(1),(Z12/F12)*(1-Y12))) | S12: =IFERROR(IF(Y12<0,SUM(AC12:AD12)/F12,L12/F12),"") | T12: =IF(M12="","",IF(M12=0,"",SUM(M12)/F12)) | V12: =IF(C12="","",IF(AND(C12=$D$2,H12=0),"Firm Payroll",IF(AND(F12=1,Y12>0.2),"Annual 20% Max Discount",IF(AND(F12=4,Y12>0.2),"Quarterly 20% Max Discount",IF(Y12>=0.6,"Discount >60%",IF(Y12<0,"Revenue Reduction Required","")))))) | X12: =IF(F12=1,"Annual Payrolls on ADP Essential Payroll",IF(F12=4,"Quarterly Payrolls on ADP Essential Payroll","")) | Y12: =IFERROR(1-((H12-M12)/SUM(Z12,AC12,AD12)),"") | Z12: =IF(C12="","",HLOOKUP($G12&'Product Selections'!$K$4&'Exhibit A'!$F12,'--'!$F$3:$AT$200,$E12+6,FALSE)*F12) | AA12: =IF($C12="","",7.95*$E12+54.95) | AB12: =IF('Product Selections'!O17="Yes",16*'Exhibit A'!F12,0) | AC12: =IF('Product Selections'!$L$11="CBA Lightning Wholesale",0,IF('Product Selections'!$L$11="CBA Lightning",0,IF($C12="",0,IF('Product Selections'!P17="",0,IF('Product Selections'!$P17="Yes",HLOOKUP($AC$10&'Exhibit A'!$F12,'--'!$F$3:$AZ$200,$E12+6,FALSE)*$F12))))) | AD12: =IF('Product Selections'!$L$11="CBA Lightning Wholesale",0,IF('Product Selections'!$L$11="CBA Lightning",0,IF('Product Selections'!Q17="",0,IF($C12="",0,IF('Product Selections'!$Q17>=0,HLOOKUP($AD$10,'--'!$F$3:$AZ$200,3,FALSE)*12*'Product Selections'!Q17))))) | AE12: =IFERROR(IF(C12="","",IF(AND(C12=$D$2,H12=0),0,IF(I12=0,H12-P12-L12-M12,IF(I12="Included",H12-P12-M12-L12,IF(I12>0,H12-M12-L12))))),"") | AG12: =AG11+0.01 | AH12: ="Estimated Payout at 100% conversion ["&AG12&"0 multiple * Annual Payroll Processing Revenue with Revenue Reduction]"
B13: =IFERROR(IF('Product Selections'!B18="","",'Product Selections'!B18),"") | C13: =IF('Product Selections'!C18="","",'Product Selections'!C18) | D13: =IF('Product Selections'!D18="","",'Product Selections'!D18) | E13: =IF('Product Selections'!E18="","",'Product Selections'!E18) | F13: =IF('Product Selections'!F18="","",'Product Selections'!F18) | G13: =IF('Product Selections'!U17="","",'Product Selections'!U17) | H13: =IFERROR(IF('Product Selections'!H18="","",'Product Selections'!H18),"") | I13: =IFERROR(IF(TRIM('Product Selections'!I18)="","",TRIM('Product Selections'!I18)),"") | K13: =IF(C13="","",IF(O13="",AE13+L13+M13,AE13+L13+M13+O13)) | L13: =IF(C13="","",SUM(AC13,AD13)*(1-Y13)) | M13: =IF(C13="","",AB13) | O13: =IF(C13="","",IF(Y13<0,Z13-AE13,"")) | P13: =IFERROR(IF(C13="","",IF(AND(C13=$D$2,H13=0),0,IF($V$8="50% ADP Discount",AA13*0.5,IF($V$8="ADP Book Price",AA13)))),"") | R13: =IF(C13="","",IF(Y13<0,(Z13/F13)*(1),(Z13/F13)*(1-Y13))) | S13: =IFERROR(IF(Y13<0,SUM(AC13:AD13)/F13,L13/F13),"") | T13: =IF(M13="","",IF(M13=0,"",SUM(M13)/F13)) | V13: =IF(C13="","",IF(AND(C13=$D$2,H13=0),"Firm Payroll",IF(AND(F13=1,Y13>0.2),"Annual 20% Max Discount",IF(AND(F13=4,Y13>0.2),"Quarterly 20% Max Discount",IF(Y13>=0.6,"Discount >60%",IF(Y13<0,"Revenue Reduction Required","")))))) | X13: =IF(F13=1,"Annual Payrolls on ADP Essential Payroll",IF(F13=4,"Quarterly Payrolls on ADP Essential Payroll","")) | Y13: =IFERROR(1-((H13-M13)/SUM(Z13,AC13,AD13)),"") | Z13: =IF(C13="","",HLOOKUP($G13&'Product Selections'!$K$4&'Exhibit A'!$F13,'--'!$F$3:$AT$200,$E13+6,FALSE)*F13) | AA13: =IF($C13="","",7.95*$E13+54.95) | AB13: =IF('Product Selections'!O18="Yes",16*'Exhibit A'!F13,0) | AC13: =IF('Product Selections'!$L$11="CBA Lightning Wholesale",0,IF('Product Selections'!$L$11="CBA Lightning",0,IF($C13="",0,IF('Product Selections'!P18="",0,IF('Product Selections'!$P18="Yes",HLOOKUP($AC$10&'Exhibit A'!$F13,'--'!$F$3:$AZ$200,$E13+6,FALSE)*$F13))))) | AD13: =IF('Product Selections'!$L$11="CBA Lightning Wholesale",0,IF('Product Selections'!$L$11="CBA Lightning",0,IF('Product Selections'!Q18="",0,IF($C13="",0,IF('Product Selections'!$Q18>=0,HLOOKUP($AD$10,'--'!$F$3:$AZ$200,3,FALSE)*12*'Product Selections'!Q18))))) | AE13: =IFERROR(IF(C13="","",IF(AND(C13=$D$2,H13=0),0,IF(I13=0,H13-P13-L13-M13,IF(I13="Included",H13-P13-M13-L13,IF(I13>0,H13-M13-L13))))),"") | AG13: =AG12+0.01 | AH13: ="Estimated Payout at 100% conversion ["&AG13&"0 multiple * Annual Payroll Processing Revenue with Revenue Reduction]"
B14: =IFERROR(IF('Product Selections'!B19="","",'Product Selections'!B19),"") | C14: =IF('Product Selections'!C19="","",'Product Selections'!C19) | D14: =IF('Product Selections'!D19="","",'Product Selections'!D19) | E14: =IF('Product Selections'!E19="","",'Product Selections'!E19) | F14: =IF('Product Selections'!F19="","",'Product Selections'!F19) | G14: =IF('Product Selections'!U18="","",'Product Selections'!U18) | H14: =IFERROR(IF('Product Selections'!H19="","",'Product Selections'!H19),"") | I14: =IFERROR(IF(TRIM('Product Selections'!I19)="","",TRIM('Product Selections'!I19)),"") | K14: =IF(C14="","",IF(O14="",AE14+L14+M14,AE14+L14+M14+O14)) | L14: =IF(C14="","",SUM(AC14,AD14)*(1-Y14)) | M14: =IF(C14="","",AB14) | O14: =IF(C14="","",IF(Y14<0,Z14-AE14,"")) | P14: =IFERROR(IF(C14="","",IF(AND(C14=$D$2,H14=0),0,IF($V$8="50% ADP Discount",AA14*0.5,IF($V$8="ADP Book Price",AA14)))),"") | R14: =IF(C14="","",IF(Y14<0,(Z14/F14)*(1),(Z14/F14)*(1-Y14))) | S14: =IFERROR(IF(Y14<0,SUM(AC14:AD14)/F14,L14/F14),"") | T14: =IF(M14="","",IF(M14=0,"",SUM(M14)/F14)) | V14: =IF(C14="","",IF(AND(C14=$D$2,H14=0),"Firm Payroll",IF(AND(F14=1,Y14>0.2),"Annual 20% Max Discount",IF(AND(F14=4,Y14>0.2),"Quarterly 20% Max Discount",IF(Y14>=0.6,"Discount >60%",IF(Y14<0,"Revenue Reduction Required","")))))) | X14: =IF(F14=1,"Annual Payrolls on ADP Essential Payroll",IF(F14=4,"Quarterly Payrolls on ADP Essential Payroll","")) | Y14: =IFERROR(1-((H14-M14)/SUM(Z14,AC14,AD14)),"") | Z14: =IF(C14="","",HLOOKUP($G14&'Product Selections'!$K$4&'Exhibit A'!$F14,'--'!$F$3:$AT$200,$E14+6,FALSE)*F14) | AA14: =IF($C14="","",7.95*$E14+54.95) | AB14: =IF('Product Selections'!O19="Yes",16*'Exhibit A'!F14,0) | AC14: =IF('Product Selections'!$L$11="CBA Lightning Wholesale",0,IF('Product Selections'!$L$11="CBA Lightning",0,IF($C14="",0,IF('Product Selections'!P19="",0,IF('Product Selections'!$P19="Yes",HLOOKUP($AC$10&'Exhibit A'!$F14,'--'!$F$3:$AZ$200,$E14+6,FALSE)*$F14))))) | AD14: =IF('Product Selections'!$L$11="CBA Lightning Wholesale",0,IF('Product Selections'!$L$11="CBA Lightning",0,IF('Product Selections'!Q19="",0,IF($C14="",0,IF('Product Selections'!$Q19>=0,HLOOKUP($AD$10,'--'!$F$3:$AZ$200,3,FALSE)*12*'Product Selections'!Q19))))) | AE14: =IFERROR(IF(C14="","",IF(AND(C14=$D$2,H14=0),0,IF(I14=0,H14-P14-L14-M14,IF(I14="Included",H14-P14-M14-L14,IF(I14>0,H14-M14-L14))))),"") | AG14: =AG13+0.01 | AH14: ="Estimated Payout at 100% conversion ["&AG14&"0 multiple * Annual Payroll Processing Revenue with Revenue Reduction]"
B15: =IFERROR(IF('Product Selections'!B20="","",'Product Selections'!B20),"") | C15: =IF('Product Selections'!C20="","",'Product Selections'!C20) | D15: =IF('Product Selections'!D20="","",'Product Selections'!D20) | E15: =IF('Product Selections'!E20="","",'Product Selections'!E20) | F15: =IF('Product Selections'!F20="","",'Product Selections'!F20) | G15: =IF('Product Selections'!U19="","",'Product Selections'!U19) | H15: =IFERROR(IF('Product Selections'!H20="","",'Product Selections'!H20),"") | I15: =IFERROR(IF(TRIM('Product Selections'!I20)="","",TRIM('Product Selections'!I20)),"") | K15: =IF(C15="","",IF(O15="",AE15+L15+M15,AE15+L15+M15+O15)) | L15: =IF(C15="","",SUM(AC15,AD15)*(1-Y15)) | M15: =IF(C15="","",AB15) | O15: =IF(C15="","",IF(Y15<0,Z15-AE15,"")) | P15: =IFERROR(IF(C15="","",IF(AND(C15=$D$2,H15=0),0,IF($V$8="50% ADP Discount",AA15*0.5,IF($V$8="ADP Book Price",AA15)))),"") | R15: =IF(C15="","",IF(Y15<0,(Z15/F15)*(1),(Z15/F15)*(1-Y15))) | S15: =IFERROR(IF(Y15<0,SUM(AC15:AD15)/F15,L15/F15),"") | T15: =IF(M15="","",IF(M15=0,"",SUM(M15)/F15)) | V15: =IF(C15="","",IF(AND(C15=$D$2,H15=0),"Firm Payroll",IF(AND(F15=1,Y15>0.2),"Annual 20% Max Discount",IF(AND(F15=4,Y15>0.2),"Quarterly 20% Max Discount",IF(Y15>=0.6,"Discount >60%",IF(Y15<0,"Revenue Reduction Required","")))))) | X15: =IF(F15=1,"Annual Payrolls on ADP Essential Payroll",IF(F15=4,"Quarterly Payrolls on ADP Essential Payroll","")) | Y15: =IFERROR(1-((H15-M15)/SUM(Z15,AC15,AD15)),"") | Z15: =IF(C15="","",HLOOKUP($G15&'Product Selections'!$K$4&'Exhibit A'!$F15,'--'!$F$3:$AT$200,$E15+6,FALSE)*F15) | AA15: =IF($C15="","",7.95*$E15+54.95) | AB15: =IF('Product Selections'!O20="Yes",16*'Exhibit A'!F15,0) | AC15: =IF('Product Selections'!$L$11="CBA Lightning Wholesale",0,IF('Product Selections'!$L$11="CBA Lightning",0,IF($C15="",0,IF('Product Selections'!P20="",0,IF('Product Selections'!$P20="Yes",HLOOKUP($AC$10&'Exhibit A'!$F15,'--'!$F$3:$AZ$200,$E15+6,FALSE)*$F15))))) | AD15: =IF('Product Selections'!$L$11="CBA Lightning Wholesale",0,IF('Product Selections'!$L$11="CBA Lightning",0,IF('Product Selections'!Q20="",0,IF($C15="",0,IF('Product Selections'!$Q20>=0,HLOOKUP($AD$10,'--'!$F$3:$AZ$200,3,FALSE)*12*'Product Selections'!Q20))))) | AE15: =IFERROR(IF(C15="","",IF(AND(C15=$D$2,H15=0),0,IF(I15=0,H15-P15-L15-M15,IF(I15="Included",H15-P15-M15-L15,IF(I15>0,H15-M15-L15))))),"") | AG15: =AG14+0.01 | AH15: ="Estimated Payout at 100% conversion ["&AG15&"0 multiple * Annual Payroll Processing Revenue with Revenue Reduction]"
B16: =IFERROR(IF('Product Selections'!B21="","",'Product Selections'!B21),"") | C16: =IF('Product Selections'!C21="","",'Product Selections'!C21) | D16: =IF('Product Selections'!D21="","",'Product Selections'!D21) | E16: =IF('Product Selections'!E21="","",'Product Selections'!E21) | F16: =IF('Product Selections'!F21="","",'Product Selections'!F21) | G16: =IF('Product Selections'!U20="","",'Product Selections'!U20) | H16: =IFERROR(IF('Product Selections'!H21="","",'Product Selections'!H21),"") | I16: =IFERROR(IF(TRIM('Product Selections'!I21)="","",TRIM('Product Selections'!I21)),"") | K16: =IF(C16="","",IF(O16="",AE16+L16+M16,AE16+L16+M16+O16)) | L16: =IF(C16="","",SUM(AC16,AD16)*(1-Y16)) | M16: =IF(C16="","",AB16) | O16: =IF(C16="","",IF(Y16<0,Z16-AE16,"")) | P16: =IFERROR(IF(C16="","",IF(AND(C16=$D$2,H16=0),0,IF($V$8="50% ADP Discount",AA16*0.5,IF($V$8="ADP Book Price",AA16)))),"") | R16: =IF(C16="","",IF(Y16<0,(Z16/F16)*(1),(Z16/F16)*(1-Y16))) | S16: =IFERROR(IF(Y16<0,SUM(AC16:AD16)/F16,L16/F16),"") | T16: =IF(M16="","",IF(M16=0,"",SUM(M16)/F16)) | V16: =IF(C16="","",IF(AND(C16=$D$2,H16=0),"Firm Payroll",IF(AND(F16=1,Y16>0.2),"Annual 20% Max Discount",IF(AND(F16=4,Y16>0.2),"Quarterly 20% Max Discount",IF(Y16>=0.6,"Discount >60%",IF(Y16<0,"Revenue Reduction Required","")))))) | X16: =IF(F16=1,"Annual Payrolls on ADP Essential Payroll",IF(F16=4,"Quarterly Payrolls on ADP Essential Payroll","")) | Y16: =IFERROR(1-((H16-M16)/SUM(Z16,AC16,AD16)),"") | Z16: =IF(C16="","",HLOOKUP($G16&'Product Selections'!$K$4&'Exhibit A'!$F16,'--'!$F$3:$AT$200,$E16+6,FALSE)*F16) | AA16: =IF($C16="","",7.95*$E16+54.95) | AB16: =IF('Product Selections'!O21="Yes",16*'Exhibit A'!F16,0) | AC16: =IF('Product Selections'!$L$11="CBA Lightning Wholesale",0,IF('Product Selections'!$L$11="CBA Lightning",0,IF($C16="",0,IF('Product Selections'!P21="",0,IF('Product Selections'!$P21="Yes",HLOOKUP($AC$10&'Exhibit A'!$F16,'--'!$F$3:$AZ$200,$E16+6,FALSE)*$F16))))) | AD16: =IF('Product Selections'!$L$11="CBA Lightning Wholesale",0,IF('Product Selections'!$L$11="CBA Lightning",0,IF('Product Selections'!Q21="",0,IF($C16="",0,IF('Product Selections'!$Q21>=0,HLOOKUP($AD$10,'--'!$F$3:$AZ$200,3,FALSE)*12*'Product Selections'!Q21))))) | AE16: =IFERROR(IF(C16="","",IF(AND(C16=$D$2,H16=0),0,IF(I16=0,H16-P16-L16-M16,IF(I16="Included",H16-P16-M16-L16,IF(I16>0,H16-M16-L16))))),"") | AG16: =AG15+0.01 | AH16: ="Estimated Payout at 100% conversion ["&AG16&"0 multiple * Annual Payroll Processing Revenue with Revenue Reduction]"
B17: =IFERROR(IF('Product Selections'!B22="","",'Product Selections'!B22),"") | C17: =IF('Product Selections'!C22="","",'Product Selections'!C22) | D17: =IF('Product Selections'!D22="","",'Product Selections'!D22) | E17: =IF('Product Selections'!E22="","",'Product Selections'!E22) | F17: =IF('Product Selections'!F22="","",'Product Selections'!F22) | G17: =IF('Product Selections'!U21="","",'Product Selections'!U21) | H17: =IFERROR(IF('Product Selections'!H22="","",'Product Selections'!H22),"") | I17: =IFERROR(IF(TRIM('Product Selections'!I22)="","",TRIM('Product Selections'!I22)),"") | K17: =IF(C17="","",IF(O17="",AE17+L17+M17,AE17+L17+M17+O17)) | L17: =IF(C17="","",SUM(AC17,AD17)*(1-Y17)) | M17: =IF(C17="","",AB17) | O17: =IF(C17="","",IF(Y17<0,Z17-AE17,"")) | P17: =IFERROR(IF(C17="","",IF(AND(C17=$D$2,H17=0),0,IF($V$8="50% ADP Discount",AA17*0.5,IF($V$8="ADP Book Price",AA17)))),"") | R17: =IF(C17="","",IF(Y17<0,(Z17/F17)*(1),(Z17/F17)*(1-Y17))) | S17: =IFERROR(IF(Y17<0,SUM(AC17:AD17)/F17,L17/F17),"") | T17: =IF(M17="","",IF(M17=0,"",SUM(M17)/F17)) | V17: =IF(C17="","",IF(AND(C17=$D$2,H17=0),"Firm Payroll",IF(AND(F17=1,Y17>0.2),"Annual 20% Max Discount",IF(AND(F17=4,Y17>0.2),"Quarterly 20% Max Discount",IF(Y17>=0.6,"Discount >60%",IF(Y17<0,"Revenue Reduction Required","")))))) | X17: =IF(F17=1,"Annual Payrolls on ADP Essential Payroll",IF(F17=4,"Quarterly Payrolls on ADP Essential Payroll","")) | Y17: =IFERROR(1-((H17-M17)/SUM(Z17,AC17,AD17)),"") | Z17: =IF(C17="","",HLOOKUP($G17&'Product Selections'!$K$4&'Exhibit A'!$F17,'--'!$F$3:$AT$200,$E17+6,FALSE)*F17) | AA17: =IF($C17="","",7.95*$E17+54.95) | AB17: =IF('Product Selections'!O22="Yes",16*'Exhibit A'!F17,0) | AC17: =IF('Product Selections'!$L$11="CBA Lightning Wholesale",0,IF('Product Selections'!$L$11="CBA Lightning",0,IF($C17="",0,IF('Product Selections'!P22="",0,IF('Product Selections'!$P22="Yes",HLOOKUP($AC$10&'Exhibit A'!$F17,'--'!$F$3:$AZ$200,$E17+6,FALSE)*$F17))))) | AD17: =IF('Product Selections'!$L$11="CBA Lightning Wholesale",0,IF('Product Selections'!$L$11="CBA Lightning",0,IF('Product Selections'!Q22="",0,IF($C17="",0,IF('Product Selections'!$Q22>=0,HLOOKUP($AD$10,'--'!$F$3:$AZ$200,3,FALSE)*12*'Product Selections'!Q22))))) | AE17: =IFERROR(IF(C17="","",IF(AND(C17=$D$2,H17=0),0,IF(I17=0,H17-P17-L17-M17,IF(I17="Included",H17-P17-M17-L17,IF(I17>0,H17-M17-L17))))),"") | AG17: =AG16+0.01 | AH17: ="Estimated Payout at 100% conversion ["&AG17&"0 multiple * Annual Payroll Processing Revenue with Revenue Reduction]"
B18: =IFERROR(IF('Product Selections'!B23="","",'Product Selections'!B23),"") | C18: =IF('Product Selections'!C23="","",'Product Selections'!C23) | D18: =IF('Product Selections'!D23="","",'Product Selections'!D23) | E18: =IF('Product Selections'!E23="","",'Product Selections'!E23) | F18: =IF('Product Selections'!F23="","",'Product Selections'!F23) | G18: =IF('Product Selections'!U22="","",'Product Selections'!U22) | H18: =IFERROR(IF('Product Selections'!H23="","",'Product Selections'!H23),"") | I18: =IFERROR(IF(TRIM('Product Selections'!I23)="","",TRIM('Product Selections'!I23)),"") | K18: =IF(C18="","",IF(O18="",AE18+L18+M18,AE18+L18+M18+O18)) | L18: =IF(C18="","",SUM(AC18,AD18)*(1-Y18)) | M18: =IF(C18="","",AB18) | O18: =IF(C18="","",IF(Y18<0,Z18-AE18,"")) | P18: =IFERROR(IF(C18="","",IF(AND(C18=$D$2,H18=0),0,IF($V$8="50% ADP Discount",AA18*0.5,IF($V$8="ADP Book Price",AA18)))),"") | R18: =IF(C18="","",IF(Y18<0,(Z18/F18)*(1),(Z18/F18)*(1-Y18))) | S18: =IFERROR(IF(Y18<0,SUM(AC18:AD18)/F18,L18/F18),"") | T18: =IF(M18="","",IF(M18=0,"",SUM(M18)/F18)) | V18: =IF(C18="","",IF(AND(C18=$D$2,H18=0),"Firm Payroll",IF(AND(F18=1,Y18>0.2),"Annual 20% Max Discount",IF(AND(F18=4,Y18>0.2),"Quarterly 20% Max Discount",IF(Y18>=0.6,"Discount >60%",IF(Y18<0,"Revenue Reduction Required","")))))) | X18: =IF(F18=1,"Annual Payrolls on ADP Essential Payroll",IF(F18=4,"Quarterly Payrolls on ADP Essential Payroll","")) | Y18: =IFERROR(1-((H18-M18)/SUM(Z18,AC18,AD18)),"") | Z18: =IF(C18="","",HLOOKUP($G18&'Product Selections'!$K$4&'Exhibit A'!$F18,'--'!$F$3:$AT$200,$E18+6,FALSE)*F18) | AA18: =IF($C18="","",7.95*$E18+54.95) | AB18: =IF('Product Selections'!O23="Yes",16*'Exhibit A'!F18,0) | AC18: =IF('Product Selections'!$L$11="CBA Lightning Wholesale",0,IF('Product Selections'!$L$11="CBA Lightning",0,IF($C18="",0,IF('Product Selections'!P23="",0,IF('Product Selections'!$P23="Yes",HLOOKUP($AC$10&'Exhibit A'!$F18,'--'!$F$3:$AZ$200,$E18+6,FALSE)*$F18))))) | AD18: =IF('Product Selections'!$L$11="CBA Lightning Wholesale",0,IF('Product Selections'!$L$11="CBA Lightning",0,IF('Product Selections'!Q23="",0,IF($C18="",0,IF('Product Selections'!$Q23>=0,HLOOKUP($AD$10,'--'!$F$3:$AZ$200,3,FALSE)*12*'Product Selections'!Q23))))) | AE18: =IFERROR(IF(C18="","",IF(AND(C18=$D$2,H18=0),0,IF(I18=0,H18-P18-L18-M18,IF(I18="Included",H18-P18-M18-L18,IF(I18>0,H18-M18-L18))))),"") | AG18: =AG17+0.01 | AH18: ="Estimated Payout at 100% conversion ["&AG18&"0 multiple * Annual Payroll Processing Revenue with Revenue Reduction]"
B19: =IFERROR(IF('Product Selections'!B24="","",'Product Selections'!B24),"") | C19: =IF('Product Selections'!C24="","",'Product Selections'!C24) | D19: =IF('Product Selections'!D24="","",'Product Selections'!D24) | E19: =IF('Product Selections'!E24="","",'Product Selections'!E24) | F19: =IF('Product Selections'!F24="","",'Product Selections'!F24) | G19: =IF('Product Selections'!U23="","",'Product Selections'!U23) | H19: =IFERROR(IF('Product Selections'!H24="","",'Product Selections'!H24),"") | I19: =IFERROR(IF(TRIM('Product Selections'!I24)="","",TRIM('Product Selections'!I24)),"") | K19: =IF(C19="","",IF(O19="",AE19+L19+M19,AE19+L19+M19+O19)) | L19: =IF(C19="","",SUM(AC19,AD19)*(1-Y19)) | M19: =IF(C19="","",AB19) | O19: =IF(C19="","",IF(Y19<0,Z19-AE19,"")) | P19: =IFERROR(IF(C19="","",IF(AND(C19=$D$2,H19=0),0,IF($V$8="50% ADP Discount",AA19*0.5,IF($V$8="ADP Book Price",AA19)))),"") | R19: =IF(C19="","",IF(Y19<0,(Z19/F19)*(1),(Z19/F19)*(1-Y19))) | S19: =IFERROR(IF(Y19<0,SUM(AC19:AD19)/F19,L19/F19),"") | T19: =IF(M19="","",IF(M19=0,"",SUM(M19)/F19)) | V19: =IF(C19="","",IF(AND(C19=$D$2,H19=0),"Firm Payroll",IF(AND(F19=1,Y19>0.2),"Annual 20% Max Discount",IF(AND(F19=4,Y19>0.2),"Quarterly 20% Max Discount",IF(Y19>=0.6,"Discount >60%",IF(Y19<0,"Revenue Reduction Required","")))))) | X19: =IF(F19=1,"Annual Payrolls on ADP Essential Payroll",IF(F19=4,"Quarterly Payrolls on ADP Essential Payroll","")) | Y19: =IFERROR(1-((H19-M19)/SUM(Z19,AC19,AD19)),"") | Z19: =IF(C19="","",HLOOKUP($G19&'Product Selections'!$K$4&'Exhibit A'!$F19,'--'!$F$3:$AT$200,$E19+6,FALSE)*F19) | AA19: =IF($C19="","",7.95*$E19+54.95) | AB19: =IF('Product Selections'!O24="Yes",16*'Exhibit A'!F19,0) | AC19: =IF('Product Selections'!$L$11="CBA Lightning Wholesale",0,IF('Product Selections'!$L$11="CBA Lightning",0,IF($C19="",0,IF('Product Selections'!P24="",0,IF('Product Selections'!$P24="Yes",HLOOKUP($AC$10&'Exhibit A'!$F19,'--'!$F$3:$AZ$200,$E19+6,FALSE)*$F19))))) | AD19: =IF('Product Selections'!$L$11="CBA Lightning Wholesale",0,IF('Product Selections'!$L$11="CBA Lightning",0,IF('Product Selections'!Q24="",0,IF($C19="",0,IF('Product Selections'!$Q24>=0,HLOOKUP($AD$10,'--'!$F$3:$AZ$200,3,FALSE)*12*'Product Selections'!Q24))))) | AE19: =IFERROR(IF(C19="","",IF(AND(C19=$D$2,H19=0),0,IF(I19=0,H19-P19-L19-M19,IF(I19="Included",H19-P19-M19-L19,IF(I19>0,H19-M19-L19))))),"") | AG19: =AG18+0.01 | AH19: ="Estimated Payout at 100% conversion ["&AG19&"0 multiple * Annual Payroll Processing Revenue with Revenue Reduction]"
B20: =IFERROR(IF('Product Selections'!B25="","",'Product Selections'!B25),"") | C20: =IF('Product Selections'!C25="","",'Product Selections'!C25) | D20: =IF('Product Selections'!D25="","",'Product Selections'!D25) | E20: =IF('Product Selections'!E25="","",'Product Selections'!E25) | F20: =IF('Product Selections'!F25="","",'Product Selections'!F25) | G20: =IF('Product Selections'!U24="","",'Product Selections'!U24) | H20: =IFERROR(IF('Product Selections'!H25="","",'Product Selections'!H25),"") | I20: =IFERROR(IF(TRIM('Product Selections'!I25)="","",TRIM('Product Selections'!I25)),"") | K20: =IF(C20="","",IF(O20="",AE20+L20+M20,AE20+L20+M20+O20)) | L20: =IF(C20="","",SUM(AC20,AD20)*(1-Y20)) | M20: =IF(C20="","",AB20) | O20: =IF(C20="","",IF(Y20<0,Z20-AE20,"")) | P20: =IFERROR(IF(C20="","",IF(AND(C20=$D$2,H20=0),0,IF($V$8="50% ADP Discount",AA20*0.5,IF($V$8="ADP Book Price",AA20)))),"") | R20: =IF(C20="","",IF(Y20<0,(Z20/F20)*(1),(Z20/F20)*(1-Y20))) | S20: =IFERROR(IF(Y20<0,SUM(AC20:AD20)/F20,L20/F20),"") | T20: =IF(M20="","",IF(M20=0,"",SUM(M20)/F20)) | V20: =IF(C20="","",IF(AND(C20=$D$2,H20=0),"Firm Payroll",IF(AND(F20=1,Y20>0.2),"Annual 20% Max Discount",IF(AND(F20=4,Y20>0.2),"Quarterly 20% Max Discount",IF(Y20>=0.6,"Discount >60%",IF(Y20<0,"Revenue Reduction Required","")))))) | X20: =IF(F20=1,"Annual Payrolls on ADP Essential Payroll",IF(F20=4,"Quarterly Payrolls on ADP Essential Payroll","")) | Y20: =IFERROR(1-((H20-M20)/SUM(Z20,AC20,AD20)),"") | Z20: =IF(C20="","",HLOOKUP($G20&'Product Selections'!$K$4&'Exhibit A'!$F20,'--'!$F$3:$AT$200,$E20+6,FALSE)*F20) | AA20: =IF($C20="","",7.95*$E20+54.95) | AB20: =IF('Product Selections'!O25="Yes",16*'Exhibit A'!F20,0) | AC20: =IF('Product Selections'!$L$11="CBA Lightning Wholesale",0,IF('Product Selections'!$L$11="CBA Lightning",0,IF($C20="",0,IF('Product Selections'!P25="",0,IF('Product Selections'!$P25="Yes",HLOOKUP($AC$10&'Exhibit A'!$F20,'--'!$F$3:$AZ$200,$E20+6,FALSE)*$F20))))) | AD20: =IF('Product Selections'!$L$11="CBA Lightning Wholesale",0,IF('Product Selections'!$L$11="CBA Lightning",0,IF('Product Selections'!Q25="",0,IF($C20="",0,IF('Product Selections'!$Q25>=0,HLOOKUP($AD$10,'--'!$F$3:$AZ$200,3,FALSE)*12*'Product Selections'!Q25))))) | AE20: =IFERROR(IF(C20="","",IF(AND(C20=$D$2,H20=0),0,IF(I20=0,H20-P20-L20-M20,IF(I20="Included",H20-P20-M20-L20,IF(I20>0,H20-M20-L20))))),"") | AG20: =AG19+0.01 | AH20: ="Estimated Payout at 100% conversion ["&AG20&"0 multiple * Annual Payroll Processing Revenue with Revenue Reduction]"
B21: =IFERROR(IF('Product Selections'!B26="","",'Product Selections'!B26),"") | C21: =IF('Product Selections'!C26="","",'Product Selections'!C26) | D21: =IF('Product Selections'!D26="","",'Product Selections'!D26) | E21: =IF('Product Selections'!E26="","",'Product Selections'!E26) | F21: =IF('Product Selections'!F26="","",'Product Selections'!F26) | G21: =IF('Product Selections'!U25="","",'Product Selections'!U25) | H21: =IFERROR(IF('Product Selections'!H26="","",'Product Selections'!H26),"") | I21: =IFERROR(IF(TRIM('Product Selections'!I26)="","",TRIM('Product Selections'!I26)),"") | K21: =IF(C21="","",IF(O21="",AE21+L21+M21,AE21+L21+M21+O21)) | L21: =IF(C21="","",SUM(AC21,AD21)*(1-Y21)) | M21: =IF(C21="","",AB21) | O21: =IF(C21="","",IF(Y21<0,Z21-AE21,"")) | P21: =IFERROR(IF(C21="","",IF(AND(C21=$D$2,H21=0),0,IF($V$8="50% ADP Discount",AA21*0.5,IF($V$8="ADP Book Price",AA21)))),"") | R21: =IF(C21="","",IF(Y21<0,(Z21/F21)*(1),(Z21/F21)*(1-Y21))) | S21: =IFERROR(IF(Y21<0,SUM(AC21:AD21)/F21,L21/F21),"") | T21: =IF(M21="","",IF(M21=0,"",SUM(M21)/F21)) | V21: =IF(C21="","",IF(AND(C21=$D$2,H21=0),"Firm Payroll",IF(AND(F21=1,Y21>0.2),"Annual 20% Max Discount",IF(AND(F21=4,Y21>0.2),"Quarterly 20% Max Discount",IF(Y21>=0.6,"Discount >60%",IF(Y21<0,"Revenue Reduction Required","")))))) | X21: =IF(F21=1,"Annual Payrolls on ADP Essential Payroll",IF(F21=4,"Quarterly Payrolls on ADP Essential Payroll","")) | Y21: =IFERROR(1-((H21-M21)/SUM(Z21,AC21,AD21)),"") | Z21: =IF(C21="","",HLOOKUP($G21&'Product Selections'!$K$4&'Exhibit A'!$F21,'--'!$F$3:$AT$200,$E21+6,FALSE)*F21) | AA21: =IF($C21="","",7.95*$E21+54.95) | AB21: =IF('Product Selections'!O26="Yes",16*'Exhibit A'!F21,0) | AC21: =IF('Product Selections'!$L$11="CBA Lightning Wholesale",0,IF('Product Selections'!$L$11="CBA Lightning",0,IF($C21="",0,IF('Product Selections'!P26="",0,IF('Product Selections'!$P26="Yes",HLOOKUP($AC$10&'Exhibit A'!$F21,'--'!$F$3:$AZ$200,$E21+6,FALSE)*$F21))))) | AD21: =IF('Product Selections'!$L$11="CBA Lightning Wholesale",0,IF('Product Selections'!$L$11="CBA Lightning",0,IF('Product Selections'!Q26="",0,IF($C21="",0,IF('Product Selections'!$Q26>=0,HLOOKUP($AD$10,'--'!$F$3:$AZ$200,3,FALSE)*12*'Product Selections'!Q26))))) | AE21: =IFERROR(IF(C21="","",IF(AND(C21=$D$2,H21=0),0,IF(I21=0,H21-P21-L21-M21,IF(I21="Included",H21-P21-M21-L21,IF(I21>0,H21-M21-L21))))),"") | AG21: =AG20+0.01 | AH21: ="Estimated Payout at 100% conversion ["&AG21&"0 multiple * Annual Payroll Processing Revenue with Revenue Reduction]"
